Traceback (most recent call last):
  File "C:\ProgramData\Anaconda3\lib\site-packages\jupyter_cache\executors\utils.py", line 58, in single_nb_execution
    executenb(
  File "C:\ProgramData\Anaconda3\lib\site-packages\nbclient\client.py", line 1305, in execute
    return NotebookClient(nb=nb, resources=resources, km=km, **kwargs).execute()
  File "C:\Users\ConquerV\AppData\Roaming\Python\Python39\site-packages\jupyter_core\utils\__init__.py", line 165, in wrapped
    return loop.run_until_complete(inner)
  File "C:\ProgramData\Anaconda3\lib\asyncio\base_events.py", line 647, in run_until_complete
    return future.result()
  File "C:\ProgramData\Anaconda3\lib\site-packages\nbclient\client.py", line 705, in async_execute
    await self.async_execute_cell(
  File "C:\ProgramData\Anaconda3\lib\site-packages\nbclient\client.py", line 1058, in async_execute_cell
    await self._check_raise_for_error(cell, cell_index, exec_reply)
  File "C:\ProgramData\Anaconda3\lib\site-packages\nbclient\client.py", line 914, in _check_raise_for_error
    raise CellExecutionError.from_cell_and_msg(cell, exec_reply_content)
nbclient.exceptions.CellExecutionError: An error occurred while executing the following cell:
------------------
data = load_numeric_data(file_path, 'Charge Count')
------------------


[1;31m--------------------------------------------------------------------[0m
[1;31mFileNotFoundError[0m                  Traceback (most recent call last)
Cell [1;32mIn[6], line 1[0m
[1;32m----> 1[0m data [38;5;241m=[39m [43mload_numeric_data[49m[43m([49m[43mfile_path[49m[43m,[49m[43m [49m[38;5;124;43m'[39;49m[38;5;124;43mCharge Count[39;49m[38;5;124;43m'[39;49m[43m)[49m

Cell [1;32mIn[5], line 11[0m, in [0;36mload_numeric_data[1;34m(file_path, column_name)[0m
[0;32m      4[0m [38;5;250m[39m[38;5;124;03m"""[39;00m
[0;32m      5[0m [38;5;124;03mLoad numeric data from a CSV file without relying on external libraries.[39;00m
[0;32m      6[0m [38;5;124;03m:param file_path: Path to the CSV file[39;00m
[0;32m      7[0m [38;5;124;03m:param column_name: Name of the numeric column[39;00m
[0;32m      8[0m [38;5;124;03m:return: List of numeric values[39;00m
[0;32m      9[0m [38;5;124;03m"""[39;00m
[0;32m     10[0m data [38;5;241m=[39m []
[1;32m---> 11[0m [38;5;28;01mwith[39;00m [38;5;28;43mopen[39;49m[43m([49m[43mfile_path[49m[43m,[49m[43m [49m[38;5;124;43m"[39;49m[38;5;124;43mr[39;49m[38;5;124;43m"[39;49m[43m)[49m [38;5;28;01mas[39;00m file:
[0;32m     12[0m     reader [38;5;241m=[39m csv[38;5;241m.[39mreader(file)
[0;32m     13[0m     header [38;5;241m=[39m [38;5;28mnext[39m(reader)  [38;5;66;03m# Read the header row[39;00m

File [1;32m~\AppData\Roaming\Python\Python39\site-packages\IPython\core\interactiveshell.py:310[0m, in [0;36m_modified_open[1;34m(file, *args, **kwargs)[0m
[0;32m    303[0m [38;5;28;01mif[39;00m file [38;5;129;01min[39;00m {[38;5;241m0[39m, [38;5;241m1[39m, [38;5;241m2[39m}:
[0;32m    304[0m     [38;5;28;01mraise[39;00m [38;5;167;01mValueError[39;00m(
[0;32m    305[0m         [38;5;124mf[39m[38;5;124m"[39m[38;5;124mIPython won[39m[38;5;124m'[39m[38;5;124mt let you open fd=[39m[38;5;132;01m{[39;00mfile[38;5;132;01m}[39;00m[38;5;124m by default [39m[38;5;124m"[39m
[0;32m    306[0m         [38;5;124m"[39m[38;5;124mas it is likely to crash IPython. If you know what you are doing, [39m[38;5;124m"[39m
[0;32m    307[0m         [38;5;124m"[39m[38;5;124myou can use builtins[39m[38;5;124m'[39m[38;5;124m open.[39m[38;5;124m"[39m
[0;32m    308[0m     )
[1;32m--> 310[0m [38;5;28;01mreturn[39;00m io_open(file, [38;5;241m*[39margs, [38;5;241m*[39m[38;5;241m*[39mkwargs)

[1;31mFileNotFoundError[0m: [Errno 2] No such file or directory: '/Users/yuxiaohan/Documents/SIPA/Computing in Context/Homework/Project 1/Department_of_Consumer_and_Worker_Protection__DCWP__Issued_Charges_20241106.csv'

